[2025-10-13T08:25:48.384+0000] {taskinstance.py:1159} INFO - Dependencies all met for dep_context=non-requeueable deps ti=<TaskInstance: dag_02_upbit_api_to_datalake.load_raw_data_to_postgres manual__2025-10-13T08:25:46.502796+00:00 [queued]>
[2025-10-13T08:25:48.387+0000] {taskinstance.py:1159} INFO - Dependencies all met for dep_context=requeueable deps ti=<TaskInstance: dag_02_upbit_api_to_datalake.load_raw_data_to_postgres manual__2025-10-13T08:25:46.502796+00:00 [queued]>
[2025-10-13T08:25:48.387+0000] {taskinstance.py:1361} INFO - Starting attempt 1 of 1
[2025-10-13T08:25:48.391+0000] {taskinstance.py:1382} INFO - Executing <Task(_PythonDecoratedOperator): load_raw_data_to_postgres> on 2025-10-13 08:25:46.502796+00:00
[2025-10-13T08:25:48.392+0000] {standard_task_runner.py:57} INFO - Started process 1278 to run task
[2025-10-13T08:25:48.394+0000] {standard_task_runner.py:84} INFO - Running: ['airflow', 'tasks', 'run', 'dag_02_upbit_api_to_datalake', 'load_raw_data_to_postgres', 'manual__2025-10-13T08:25:46.502796+00:00', '--job-id', '15', '--raw', '--subdir', 'DAGS_FOLDER/upbit_api_data_lake_dag.py', '--cfg-path', '/tmp/tmpqupwzmli']
[2025-10-13T08:25:48.395+0000] {standard_task_runner.py:85} INFO - Job 15: Subtask load_raw_data_to_postgres
[2025-10-13T08:25:48.413+0000] {task_command.py:415} INFO - Running <TaskInstance: dag_02_upbit_api_to_datalake.load_raw_data_to_postgres manual__2025-10-13T08:25:46.502796+00:00 [running]> on host d5c5bb7a9cf7
[2025-10-13T08:25:48.457+0000] {taskinstance.py:1660} INFO - Exporting env vars: AIRFLOW_CTX_DAG_OWNER='airflow' AIRFLOW_CTX_DAG_ID='dag_02_upbit_api_to_datalake' AIRFLOW_CTX_TASK_ID='load_raw_data_to_postgres' AIRFLOW_CTX_EXECUTION_DATE='2025-10-13T08:25:46.502796+00:00' AIRFLOW_CTX_TRY_NUMBER='1' AIRFLOW_CTX_DAG_RUN_ID='manual__2025-10-13T08:25:46.502796+00:00'
[2025-10-13T08:25:48.465+0000] {taskinstance.py:1943} ERROR - Task failed with exception
Traceback (most recent call last):
  File "/home/airflow/.local/lib/python3.8/site-packages/airflow/decorators/base.py", line 221, in execute
    return_value = super().execute(context)
  File "/home/airflow/.local/lib/python3.8/site-packages/airflow/operators/python.py", line 192, in execute
    return_value = self.execute_callable()
  File "/home/airflow/.local/lib/python3.8/site-packages/airflow/operators/python.py", line 209, in execute_callable
    return self.python_callable(*self.op_args, **self.op_kwargs)
  File "/opt/airflow/dags/upbit_api_data_lake_dag.py", line 59, in load_raw_data_to_postgres
    pg_hook.insert_rows(
  File "/home/airflow/.local/lib/python3.8/site-packages/airflow/providers/common/sql/hooks/sql.py", line 495, in insert_rows
    with closing(self.get_conn()) as conn:
  File "/home/airflow/.local/lib/python3.8/site-packages/airflow/providers/postgres/hooks/postgres.py", line 124, in get_conn
    conn = deepcopy(self.connection or self.get_connection(conn_id))
  File "/home/airflow/.local/lib/python3.8/site-packages/airflow/hooks/base.py", line 72, in get_connection
    conn = Connection.get_connection_from_secrets(conn_id)
  File "/home/airflow/.local/lib/python3.8/site-packages/airflow/models/connection.py", line 477, in get_connection_from_secrets
    raise AirflowNotFoundException(f"The conn_id `{conn_id}` isn't defined")
airflow.exceptions.AirflowNotFoundException: The conn_id `postgres_default` isn't defined
[2025-10-13T08:25:48.467+0000] {taskinstance.py:1400} INFO - Marking task as FAILED. dag_id=dag_02_upbit_api_to_datalake, task_id=load_raw_data_to_postgres, execution_date=20251013T082546, start_date=20251013T082548, end_date=20251013T082548
[2025-10-13T08:25:48.470+0000] {standard_task_runner.py:104} ERROR - Failed to execute job 15 for task load_raw_data_to_postgres (The conn_id `postgres_default` isn't defined; 1278)
[2025-10-13T08:25:48.493+0000] {local_task_job_runner.py:228} INFO - Task exited with return code 1
[2025-10-13T08:25:48.501+0000] {taskinstance.py:2784} INFO - 0 downstream tasks scheduled from follow-on schedule check
